Workbook

Sheet Export
A1: ReleaseID | B1: PMInterfaceID | C1: OEM | D1: Region | E1: OwnerOrg | F1: TaskOrReview ID | G1: TaskOrReview Creation Date | H1: TotalSpent Hrs
A2: 5417327 | B2: BM-00087996 | C2: DAG | D2: India | E2: HCL, MS/PJ-OM-NE-VM | F2: 5433090 | G2: 45706 | H2: 4 | I2: =VLOOKUP(F2,Sheet1!G2:H272,2,FALSE) -> #N/A
A3: 5417327 | B3: BM-00087996 | C3: DAG | D3: India | E3: HCL, MS/PJ-OM-NE-VM | F3: 5471257 | G3: 45716 | H3: 17 | I3: =VLOOKUP(F3,Sheet1!$G$2:$H$272,2,FALSE) -> #N/A
A4: 5417327 | B4: BM-00087996 | C4: DAG | D4: India | E4: HCL, MS/PJ-OM-NE-VM | F4: 5483332 | G4: 45720 | H4: 25.5 | I4: =VLOOKUP(F4,Sheet1!$G$2:$H$272,2,FALSE) -> #N/A
A5: 5417327 | B5: BM-00087996 | C5: DAG | D5: India | E5: MS/EBD11-VM | F5: 5690851 | G5: 45782 | H5: 2 | I5: =VLOOKUP(F5,Sheet1!$G$2:$H$272,2,FALSE) -> #N/A
A6: 5417327 | B6: BM-00087996 | C6: DAG | D6: India | E6: MS/EBD11-VM | F6: 5690854 | G6: 45782 | H6: 2 | I6: =VLOOKUP(F6,Sheet1!$G$2:$H$272,2,FALSE) -> #N/A
A7: 5417327 | B7: BM-00087996 | C7: DAG | D7: India | E7: MS/EBD11-VM | F7: 5690855 | G7: 45782 | H7: 4 | I7: =VLOOKUP(F7,Sheet1!$G$2:$H$272,2,FALSE) -> #N/A
A8: 5417327 | B8: BM-00087996 | C8: DAG | D8: India | E8: MS/EBV3-SWC | F8: 5492053 | G8: 45722 | H8: 2 | I8: =VLOOKUP(F8,Sheet1!$G$2:$H$272,2,FALSE) -> #N/A
A9: 5417327 | B9: BM-00087996 | C9: DAG | D9: India | E9: MS/EBV3-SWC | F9: 5492054 | G9: 45722 | H9: 2 | I9: =VLOOKUP(F9,Sheet1!$G$2:$H$272,2,FALSE) -> #N/A
A10: 5417327 | B10: BM-00087996 | C10: DAG | D10: India | E10: MS/EBV3-SWC | F10: 5557637 | G10: 45741 | H10: 17 | I10: =VLOOKUP(F10,Sheet1!$G$2:$H$272,2,FALSE) -> #N/A
A11: 5417327 | B11: BM-00087996 | C11: DAG | D11: India | E11: MS/EBV3-SWC | F11: 5563140 | G11: 45742 | H11: 3.5 | I11: =VLOOKUP(F11,Sheet1!$G$2:$H$272,2,FALSE) -> #N/A
A12: 5417327 | B12: BM-00087996 | C12: DAG | D12: India | E12: MS/EBV3-SWC | F12: 5579099 | G12: 45747 | H12: 68 | I12: =VLOOKUP(F12,Sheet1!$G$2:$H$272,2,FALSE) -> #N/A
A13: 5417327 | B13: BM-00087996 | C13: DAG | D13: India | E13: MS/EBV3-SWC | F13: 5616541 | G13: 45756 | H13: 1 | I13: =VLOOKUP(F13,Sheet1!$G$2:$H$272,2,FALSE) -> #N/A
A14: 5417327 | B14: BM-00087996 | C14: DAG | D14: India | E14: MS/EHE11-VM | G14: 45840 | H14: 3 | I14: =VLOOKUP(F14,Sheet1!$G$2:$H$272,2,FALSE) -> #N/A
A15: 5417327 | B15: BM-00087996 | C15: DAG | D15: India | E15: MS/EHE11-VM | F15: 5400612 | G15: 45698 | H15: 2 | I15: =VLOOKUP(F15,Sheet1!$G$2:$H$272,2,FALSE) -> #N/A
A16: 5417327 | B16: BM-00087996 | C16: DAG | D16: India | E16: MS/EHE11-VM | F16: 5433093 | G16: 45706 | H16: 1 | I16: =VLOOKUP(F16,Sheet1!$G$2:$H$272,2,FALSE) -> #N/A
A17: 5417327 | B17: BM-00087996 | C17: DAG | D17: India | E17: MS/EHE11-VM | F17: 5483335 | G17: 45720 | H17: 2 | I17: =VLOOKUP(F17,Sheet1!$G$2:$H$272,2,FALSE) -> #N/A
A18: 5417327 | B18: BM-00087996 | C18: DAG | D18: India | E18: MS/EHE11-VM | F18: 5552581 | G18: 45740 | H18: 9 | I18: =VLOOKUP(F18,Sheet1!$G$2:$H$272,2,FALSE) -> #N/A
A19: 5417327 | B19: BM-00087996 | C19: DAG | D19: India | E19: MS/EHE11-VM | F19: 5552583 | G19: 45740 | H19: 12.5 | I19: =VLOOKUP(F19,Sheet1!$G$2:$H$272,2,FALSE) -> #N/A
A20: 5417327 | B20: BM-00087996 | C20: DAG | D20: India | E20: MS/EHE11-VM | F20: 5552584 | G20: 45740 | H20: 0.5 | I20: =VLOOKUP(F20,Sheet1!$G$2:$H$272,2,FALSE) -> #N/A
A21: 5417327 | B21: BM-00087996 | C21: DAG | D21: India | E21: MS/EHE11-VM | F21: 5552586 | G21: 45740 | H21: 1 | I21: =VLOOKUP(F21,Sheet1!$G$2:$H$272,2,FALSE) -> #N/A
A22: 5417327 | B22: BM-00087996 | C22: DAG | D22: India | E22: MS/EHE11-VM | F22: 5622649 | G22: 45757 | H22: 1.5 | I22: =VLOOKUP(F22,Sheet1!$G$2:$H$272,2,FALSE) -> #N/A
A23: 5417327 | B23: BM-00087996 | C23: DAG | D23: India | E23: MS/EHE11-VM | F23: 5622655 | G23: 45757 | H23: 1.5 | I23: =VLOOKUP(F23,Sheet1!$G$2:$H$272,2,FALSE) -> #N/A
A24: 5417327 | B24: BM-00087996 | C24: DAG | D24: India | E24: MS/EHE11-VM | F24: 5622657 | G24: 45757 | H24: 3 | I24: =VLOOKUP(F24,Sheet1!$G$2:$H$272,2,FALSE) -> #N/A
A25: 5417327 | B25: BM-00087996 | C25: DAG | D25: India | E25: MS/EHE11-VM | F25: 5622659 | G25: 45757 | H25: 2 | I25: =VLOOKUP(F25,Sheet1!$G$2:$H$272,2,FALSE) -> #N/A
A26: 5417327 | B26: BM-00087996 | C26: DAG | D26: India | E26: MS/EHE11-VM | F26: 5622660 | G26: 45757 | H26: 1 | I26: =VLOOKUP(F26,Sheet1!$G$2:$H$272,2,FALSE) -> #N/A
... A31: 5417327 | B31: BM-00087996 | C31: DAG | D31: India | E31: MS/EHE11-VM | F31: 5690862 | G31: 45782 | H31: 1 | I31: =VLOOKUP(F31,Sheet1!$G$2:$H$272,2,FALSE) -> #N/A
A32: 5417327 | B32: BM-00087996 | C32: DAG | D32: India | E32: MS/EHE2-VM | G32: 45678 | H32: 12 | I32: =VLOOKUP(F32,Sheet1!$G$2:$H$272,2,FALSE) -> #N/A
A33: 5417327 | B33: BM-00087996 | C33: DAG | D33: India | E33: MS/EHE2-VM | G33: 45699 | H33: 12 | I33: =VLOOKUP(F33,Sheet1!$G$2:$H$272,2,FALSE) -> #N/A
A34: 5417327 | B34: BM-00087996 | C34: DAG | D34: India | E34: MS/EHE2-VM | G34: 45725 | H34: 103.5 | I34: =VLOOKUP(F34,Sheet1!$G$2:$H$272,2,FALSE) -> #N/A
A35: 5417327 | B35: BM-00087996 | C35: DAG | D35: India | E35: MS/EHE2-VM | G35: 45735 | H35: 12.5 | I35: =VLOOKUP(F35,Sheet1!$G$2:$H$272,2,FALSE) -> #N/A
A36: 5417327 | B36: BM-00087996 | C36: DAG | D36: India | E36: MS/EHE2-VM | G36: 45744 | H36: 93 | I36: =VLOOKUP(F36,Sheet1!$G$2:$H$272,2,FALSE) -> #N/A
A37: 5417327 | B37: BM-00087996 | C37: DAG | D37: India | E37: MS/EHE2-VM | G37: 45758 | H37: 11 | I37: =VLOOKUP(F37,Sheet1!$G$2:$H$272,2,FALSE) -> #N/A
A38: 5417327 | B38: BM-00087996 | C38: DAG | D38: India | E38: MS/EHE2-VM | G38: 45764 | H38: 48.5 | I38: =VLOOKUP(F38,Sheet1!$G$2:$H$272,2,FALSE) -> #N/A
A39: 5417327 | B39: BM-00087996 | C39: DAG | D39: India | E39: MS/EHE2-VM | G39: 45768 | H39: 58 | I39: =VLOOKUP(F39,Sheet1!$G$2:$H$272,2,FALSE) -> #N/A
A40: 5417327 | B40: BM-00087996 | C40: DAG | D40: India | E40: MS/EHE2-VM | G40: 45777 | H40: 8 | I40: =VLOOKUP(F40,Sheet1!$G$2:$H$272,2,FALSE) -> #N/A
A41: 5417327 | B41: BM-00087996 | C41: DAG | D41: India | E41: MS/EHE2-VM | G41: 45779 | H41: 18.5 | I41: =VLOOKUP(F41,Sheet1!$G$2:$H$272,2,FALSE) -> #N/A
A42: 5417327 | B42: BM-00087996 | C42: DAG | D42: India | E42: MS/EHE2-VM | G42: 45797 | H42: 9.5 | I42: =VLOOKUP(F42,Sheet1!$G$2:$H$272,2,FALSE) -> #N/A
A43: 5417327 | B43: BM-00087996 | C43: DAG | D43: India | E43: MS/EHE2-VM | F43: 5375455 | G43: 45691 | H43: 6 | I43: =VLOOKUP(F43,Sheet1!$G$2:$H$272,2,FALSE) -> #N/A
A44: 5417327 | B44: BM-00087996 | C44: DAG | D44: India | E44: MS/EHE2-VM | F44: 5403743 | G44: 45699 | H44: 4.25 | I44: =VLOOKUP(F44,Sheet1!$G$2:$H$272,2,FALSE) -> #N/A
...

Sheet Sheet1
A1: Release ID | B1: PM ID | C1: Release Owner | D1: Release Created | E1: Release Resolved | F1: Category | G1: Task ID | H1: Hours | I1: Type | J1: Department | K1: Task Owner | L1: Country | M1: Title | N1: Task Created | O1: Created_Year
A2: 5417327 | B2: BM-00087996 | C2: Febin Sheron P S (MS/EMB1-VM) | D2: 45701 | E2: 31-03-2026 | F2: DCOM DEV | G2: 5495021 | H2: 8 | I2: task | J2: dsm - diagnosis and system management | K2: Abishek K S D (MS/EHE2-VM) | L2: India | M2: [DSM][Impl.][MRA2][ESP][SSP][Impl.] Update the INS Calibration DEM Structure | N2: 06-03-2025 | O2: 2025 | P2: =VLOOKUP(G2,Export!F1:H130,2,FALSE) -> #N/A
A3: 5417327 | B3: BM-00087996 | C3: Febin Sheron P S (MS/EMB1-VM) | D3: 45701 | E3: 31-03-2026 | F3: DCOM DEV | G3: 5495022 | H3: 2 | I3: com.bosch.rtc.configuration.workitemtype.type.review | J3: dsm - diagnosis and system management | K3: Akash Bhaskara Mogaveera (MS/EHE2-VM) | L3: India | M3: [Review][DSM][Impl.][MRA2][ESP][SSP][Impl.] Update the INS Calibration DEM Structure | N3: 06-03-2025 | O3: 2025
A4: 5417327 | B4: BM-00087996 | C4: Febin Sheron P S (MS/EMB1-VM) | D4: 45701 | E4: 31-03-2026 | F4: DCOM DEV | G4: 5499082 | H4: 1 | I4: task | J4: dsm - diagnosis and system management | K4: Abishek K S D (MS/EHE2-VM) | L4: India | M4: [DSM][ReqEng][MRA2][ESP][SSP] Takeover INS and SAS OBD relevant changes from mainstream | N4: 07-03-2025 | O4: 2025
A5: 5417327 | B5: BM-00087996 | C5: Febin Sheron P S (MS/EMB1-VM) | D5: 45701 | E5: 31-03-2026 | F5: DCOM DEV | G5: 5465884 | H5: 1 | I5: com.bosch.rtc.configuration.workitemtype.type.review | J5: dsm - diagnosis and system management | K5: Latha Soundararajan (MS/EHE2-VM) | L5: India | M5: [DSM][ReqEng][MRA2][iBooster/ESP][BSW/ASW][SWFS Rev] END/curability issue | N5: 27-02-2025 | O5: 2025
A6: 5417327 | B6: BM-00087996 | C6: Febin Sheron P S (MS/EMB1-VM) | D6: 45701 | E6: 31-03-2026 | F6: DCOM DEV | G6: 5465885 | H6: 20.5 | I6: task | J6: dsm - diagnosis and system management | K6: Akash Bhaskara Mogaveera (MS/EHE2-VM) | L6: India | M6: [DSM][ReqEng][MRA2][iBooster/ESP][BSW/ASW][SWFS Dev] END/curability issue | N6: 27-02-2025 | O6: 2025
A7: 5417327 | B7: BM-00087996 | C7: Febin Sheron P S (MS/EMB1-VM) | D7: 45701 | E7: 31-03-2026 | F7: DCOM DEV | G7: 5465876 | H7: 2 | I7: com.bosch.rtc.configuration.workitemtype.type.review | J7: dsm - diagnosis and system management | K7: Latha Soundararajan (MS/EHE2-VM) | L7: India | M7: [Review][DSM][Impl.][MRA2][iBooster/ESP][BSW/ASW][Impl.] END/curability issue | N7: 27-02-2025 | O7: 2025
A8: 5417327 | B8: BM-00087996 | C8: Febin Sheron P S (MS/EMB1-VM) | D8: 45701 | E8: 31-03-2026 | F8: DCOM DEV | G8: 5465875 | H8: 27.5 | I8: task | J8: dsm - diagnosis and system management | K8: Akash Bhaskara Mogaveera (MS/EHE2-VM) | L8: India | M8: [DSM][Impl.][MRA2][iBooster/ESP][BSW/ASW][Impl.] END/curability issue | N8: 27-02-2025 | O8: 2025
A9: 5417327 | B9: BM-00087996 | C9: Febin Sheron P S (MS/EMB1-VM) | D9: 45701 | E9: 31-03-2026 | F9: DCOM DEV | G9: 5578382 | H9: 2.5 | I9: task | J9: dcom - customer diagnosis | K9: Latha Soundararajan (MS/EHE2-VM) | L9: India | M9: [MRA2] [DCOM]Development activities and Defect analysis _BL30_SP03 | N9: 31-03-2025 | O9: 2025
A10: 5417327 | B10: BM-00087996 | C10: Febin Sheron P S (MS/EMB1-VM) | D10: 45701 | E10: 31-03-2026 | F10: DCOM DEV | G10: 5572855 | H10: 93 | I10: task | J10: dcom - customer diagnosis | K10: Priya Dharshini Arumugam (MS/EHE2-VM) | L10: India | M10: [MRA2] [DCOM]Development activities and Defect analysis _BL30_SP03 | N10: 28-03-2025 | O10: 2025
A11: 5417327 | B11: BM-00087996 | C11: Febin Sheron P S (MS/EMB1-VM) | D11: 45701 | E11: 31-03-2026 | F11: DCOM DEV | G11: 5572861 | H11: 4 | I11: task | J11: dcom - customer diagnosis | K11: Priya Dharshini Arumugam (MS/EHE2-VM) | L11: India | M11: [MRA2] [DCOM]Development activities and Defect analysis _BL30_SP03 | N11: 28-03-2025 | O11: 2025
A12: 5417327 | B12: BM-00087996 | C12: Febin Sheron P S (MS/EMB1-VM) | D12: 45701 | E12: 31-03-2026 | F12: DCOM DEV | G12: 5574239 | H12: 48 | I12: task | J12: dcom - customer diagnosis | K12: EXTERNAL Ramamurthy Ragavi (T&amp;S (Technology and Strategy), VM/ESB3-CB) | L12: Germany | M12: [MRA2] [DCOM]Development activities and Defect analysis _BL30_SP03 | N12: 28-03-2025 | O12: 2025
A13: 5417327 | B13: BM-00087996 | C13: Febin Sheron P S (MS/EMB1-VM) | D13: 45701 | E13: 31-03-2026 | F13: NET REWORK | G13: 5400612 | H13: 2 | I13: task | J13: hmi - human machine interface | K13: Nivedha Aruchamy (MS/EHE11-VM) | L13: India | M13: [HMI][Impl.][MRA2][HMI][ESP][Impl.] V12 Engine Vehicles in USA and CANADA gives out Brake Defective Message for Level 1 failures - To be corrected | N13: 10-02-2025 | O13: 2025
A14: 5417327 | B14: BM-00087996 | C14: Febin Sheron P S (MS/EMB1-VM) | D14: 45701 | E14: 31-03-2026 | F14: NET DEV | G14: 5426039 | H14: 3 | I14: task | J14: var - variant coding and variant handling | K14: Praveen V (MS/EHE11-VM) | L14: India | M14: [BSW]MRA2][ESP/IB2][VAR] DDL Review BL28S7 vs BL29S2V01 | N14: 17-02-2025 | O14: 2025
... A17: 5417327 | B17: BM-00087996 | C17: Febin Sheron P S (MS/EMB1-VM) | D17: 45701 | E17: 31-03-2026 | F17: DCOM DEV | G17: 5333619 | H17: 29 | I17: task | J17: dsm - diagnosis and system management | K17: Abishek K S D (MS/EHE2-VM) | L17: India | M17: [DSM][ReqEng+Impl][MRA2][ESP/IB2][DSM][Impl.] DDL Review BL28S7 vs BL29S2V00 | N17: 16-01-2025 | O17: 2025
A18: 5417327 | B18: BM-00087996 | C18: Febin Sheron P S (MS/EMB1-VM) | D18: 45701 | E18: 31-03-2026 | F18: DSM DEV | G18: 5435310 | H18: 3 | I18: task | J18: test mbg bsw obd | K18: Ambika Gunasekaran (MS/EMB2-VM) | L18: India | M18: [Test Verification][TestDev-ISW-OBD][MRA2][ESP/IB][ZEVonUDS] Service 0x19 - 0x04 Freeze Frame data Not Receiving for DID F40D, F449, F442 | N18: 19-02-2025 | O18: 2025
A19: 5417327 | B19: BM-00087996 | C19: Febin Sheron P S (MS/EMB1-VM) | D19: 45701 | E19: 31-03-2026 | F19: DCOM DEV | G19: 5578632 | H19: 7 | I19: task | J19: dcom - customer diagnosis | K19: Ambika Gunasekaran (MS/EMB2-VM) | L19: India | M19: [Test Verification][TestDev]Fix for Defect:[MRA2][ESP][IB2] Extended Data class is wrongly mapped for some OBD and NON-OBD DTCs | N19: 31-03-2025 | O19: 2025
A20: 5417327 | B20: BM-00087996 | C20: Febin Sheron P S (MS/EMB1-VM) | D20: 45701 | E20: 31-03-2026 | F20: DCOM DEV | G20: 5692768 | H20: 6 | I20: task | J20: test mbg bsw dcom | K20: Ambika Gunasekaran (MS/EMB2-VM) | L20: India | M20: [Test Verification][MBG][MRA2][ESP/IB] :OBD EXtended data records and Snapshot Data Record Received&nbsp; NRC31 in UDS address | N20: 06-05-2025 | O20: 2025
A21: 5417327 | B21: BM-00087996 | C21: Febin Sheron P S (MS/EMB1-VM) | D21: 45701 | E21: 31-03-2026 | F21: DCOM DEV | G21: 5651826 | H21: 5 | I21: task | J21: dcom - customer diagnosis | K21: Ambika Gunasekaran (MS/EMB2-VM) | L21: India | M21: [Test Execution][TestExec][MRA2][ESP/IB2][DCOM][DSM] Service 0x19 Run time Optimization - Long term fix integration | N21: 21-04-2025 | O21: 2025
A22: 5417327 | B22: BM-00087996 | C22: Febin Sheron P S (MS/EMB1-VM) | D22: 45701 | E22: 31-03-2026 | F22: DSM DEV | G22: 5494014 | H22: 2 | I22: task | J22: test mbg bsw obd | K22: Ambika Gunasekaran (MS/EMB2-VM) | L22: India | M22: [Test Verification][TestDev-ISW-OBD][MRA2][ESP/IB2][DCOM] OBD Tester should not support UDS services - Missing Implementation/Updates - Step2 | N22: 06-03-2025 | O22: 2025
A23: 5417327 | B23: BM-00087996 | C23: Febin Sheron P S (MS/EMB1-VM) | D23: 45701 | E23: 31-03-2026 | F23: DSM DEV | G23: 5641907 | H23: 2 | I23: com.bosch.rtc.configuration.workitemtype.type.review | J23: test mbg bsw obd | K23: Ambika Gunasekaran (MS/EMB2-VM) | L23: India | M23: [Test Verification][Test Development][TestDev]Fix for Defect: [Daimler 14668253] [ZEVonUDS] [ESP] [EBB] [MRA2] F431 &quot;Distance since diagnostic trouble codes cleared&quot; is incrementing in Idle | N23: 16-04-2025 | O23: 2025
A24: 5417327 | B24: BM-00087996 | C24: Febin Sheron P S (MS/EMB1-VM) | D24: 45701 | E24: 31-03-2026 | F24: DCOM DEV | G24: 5660709 | H24: 4 | I24: task | J24: dcom - customer diagnosis | K24: Ambika Gunasekaran (MS/EMB2-VM) | L24: India | M24: [Test Execution][TestExec]Fix for Defect: [MRA2][DSM] :OBD data records observed in OBDClassic_NotAvailable_Coded 19 06 response message in UDS address | N24: 23-04-2025 | O24: 2025
A25: 5417327 | B25: BM-00087996 | C25: Febin Sheron P S (MS/EMB1-VM) | D25: 45701 | E25: 31-03-2026 | F25: DCOM DEV | G25: 5563294 | H25: 3 | I25: task | J25: obdonuds sw - on board diagnosis on uds sw | K25: Ambika Gunasekaran (MS/EMB2-VM) | L25: India | M25: [Test Execution][TestExec][MRA2][ESP][OBD][DCOM] CMT implementation - OBDonUDS + OBDClassic CAT5 - Minor FW update (BL30) | N25: 26-03-2025 | O25: 2025
A26: 5417327 | B26: BM-00087996 | C26: Febin Sheron P S (MS/EMB1-VM) | D26: 45701 | E26: 31-03-2026 | F26: DCOM DEV | G26: 5800715 | H26: 13.5 | I26: task | J26: dsm - diagnosis and system management | K26: Ambika Gunasekaran (MS/EMB2-VM) | L26: India | M26: [Test Execution][TestExec][MRA2][ESP][OBD][DCOM] CMT implementation - OBDonUDS + OBDClassic CAT5 (BL30 Sp04 V02) | N26: 06-06-2025 | O26: 2025
A27: 5417327 | B27: BM-00087996 | C27: Febin Sheron P S (MS/EMB1-VM) | D27: 45701 | E27: 31-03-2026 | F27: DSM DEV | G27: 5614914 | H27: 19.5 | I27: task | J27: test mbg bsw obd | K27: Ambika Gunasekaran (MS/EMB2-VM) | L27: India | M27: [Test Verification][TestDev]: OBDOnUDS / ZEVOnUDS Regression | N27: 08-04-2025 | O27: 2025
A28: 5417327 | B28: BM-00087996 | C28: Febin Sheron P S (MS/EMB1-VM) | D28: 45701 | E28: 31-03-2026 | F28: NET DEV | G28: 5457422 | H28: 6 | I28: task | J28: test mbg bsw var | K28: Loganathan Murugan (MS/EIN32-VM) | L28: India | M28: [Test Verification][TestDev-VAR][MRA2][ESP/IB2][UDS][OBDonUDS] Freeze frame(19 04) on ZEVonUDS to be Codable through VAR code - Activation | N28: 25-02-2025 | O28: 2025
A29: 5417327 | B29: BM-00087996 | C29: Febin Sheron P S (MS/EMB1-VM) | D29: 45701 | E29: 31-03-2026 | F29: DCOM DEV | G29: 5566880 | H29: 4.5 | I29: task | J29: test mbg bsw dcom | K29: Ambika Gunasekaran (MS/EMB2-VM) | L29: India | M29: [Test Verification][TestDev][MRA2] [ESP/IB2] [OBDonUDS/ZEVonUDS] Response table is not accordance with SW for $19 04 of OBDonUDS and ZEVonUDS | N29: 27-03-2025 | O29: 2025
A30: 5417327 | B30: BM-00087996 | C30: Febin Sheron P S (MS/EMB1-VM) | D30: 45701 | E30: 31-03-2026 | F30: DCOM DEV | G30: 5499028 | H30: 2 | I30: task | J30: dcom - customer diagnosis | K30: Ambika Gunasekaran (MS/EMB2-VM) | L30: India | M30: [Test Execution][TestExec][MRA2] [DEM][OBDonUDS][ZEVonUDS] Take over of Defect 5421751 from MS - $19 04 Freeze Frame record data is duplicated when same DID is configured simultaneously for OBDonUDS &amp; ZEVonUDS | N30: 07-03-2025 | O30: 2025
... A272: 5417327 | B272: BM-00087996 | C272: Febin Sheron P S (MS/EMB1-VM) | D272: 45701 | E272: 31-03-2026 | F272: NET REWORK | G272: 5433090 | H272: 4 | I272: task | J272: net - network communication | K272: D_EXTERNAL Ashish Pavan Vasana (HCL, MS/PJ-OM-NE-VM) | L272: India | M272: [NET][Impl.]Fix for Defect: [MRA2][NET][DSM][ESP][EBB][Impl.] - UMID not assigned | N272: 18-02-2025 | O272: 2025
